<?xml version="1.0"?>
<robot  xmlns:xacro="http://www.ros.org/wiki/xacro" name="first_model">
    <xacro:include filename="$(find gradsim)/urdf/controllers_sensors.gazebo" />
    <xacro:macro name="default_wheel" params="name rot" >
        <link name="${name}">
            <visual>
                <geometry>
                    <!--cylinder  length=".1" radius="0.13" /-->
                    <mesh filename="package://gradsim/meshes/wheel.dae" scale="1.3 1.3 1.3"/>
                    
                </geometry>
                <origin rpy="${rot} 0 0" xyz="0 0 0.0"/>
                <!--material name="red"/-->
                
            </visual>
            <collision>
                    <geometry>
                            <mesh filename="package://gradsim/meshes/wheel.dae" scale="1.3 1.3 1.3"/>
                    </geometry>
                    <origin rpy="${rot} 0 0" xyz="0 0 0.0"/>
                    <material name="red"/>
            </collision>
            <inertial>
                    <origin rpy="${rot} 0 0" xyz="0 0 0"/>
                    <mass value="1.0"/>
                    <inertia
                        ixx="0.01" ixy="0" ixz="0"
                        iyy="0.01" iyz="0"
                        izz="0.01"
                    />
            </inertial>
        </link>
    </xacro:macro>
    <xacro:macro name="wheel_joint" params="child_name cenx ceny">
        <joint name="base_to_${child_name}" type="continuous">
            <axis rpy="0 0 0" xyz="0 1 0"/>
            <parent link="base_link"/>
            <child link="${child_name}"/>
            <origin xyz="${cenx} ${ceny} -0.03"/>
        </joint>

    </xacro:macro>
    <material name="blue">
        <color rgba="0 0 0.8 1"/>
    </material> 
    <material name="black">
            <color rgba="0 0 0 1"/>
        </material> 
    <material name="red">
            <color rgba="0.7 .1 0 1"/>
    </material> 

        
    <link name="base_footprint" pose="0 0 0 0 0 0"/>
    <link name="base_link">
        <visual>
            <geometry>
                <box size="0.7 0.5 0.2" />
            </geometry>
            <material name="blue"/>
        </visual>
        <collision>
                <geometry>
                        <box size="0.7 0.5 0.2" />
                </geometry>
                <material name="blue"/>
        </collision>
        <inertial>
                <mass value="8.0"/>
                <inertia
                    ixx="1.1" ixy="0" ixz="0"
                    iyy="1.1" iyz="0"
                    izz="1.1"
                />
        </inertial>
    </link>

    <joint name="basel_footl" type="fixed">
            <origin rpy="0 0 0" xyz="0 0 0.12"/>
            <parent link="base_footprint" />
            <child link ="base_link" />

    </joint>
    
    
    <xacro:default_wheel name="right_back_wheel" rot="3.1415" />
    <xacro:default_wheel name="right_forward_wheel" rot="3.1415" />

    <xacro:wheel_joint child_name="right_forward_wheel" cenx="0.25" ceny="0.32" />
    <xacro:wheel_joint child_name="right_back_wheel" cenx="-0.25" ceny="0.32" />
    <xacro:default_wheel name="left_back_wheel" rot="0.0" />

    <xacro:default_wheel name="left_forward_wheel" rot="0.0" />
    
    <xacro:wheel_joint child_name="left_forward_wheel" cenx="0.25" ceny="-0.32" />
    <xacro:wheel_joint child_name="left_back_wheel" cenx="-0.25" ceny="-0.32" />
    <link name="imu_link">
        <visual>
            <geometry>
                <box size="0.05 0.05 0.005" />
            </geometry>
            <origin rpy="0 0 0" xyz="0 0 0.101"/>
            <material name="black"/>
        </visual>
        <collision>
                <geometry>
                    <box size="0.05 0.05 0.005" />
                </geometry>
                <origin rpy="0 0 0" xyz="0 0 0.101"/>
                <material name="black"/>
        </collision>
        <inertial>
                <origin rpy="0 0 0" xyz="0 0 0.101"/>
                <mass value="0.0001"/>
                <inertia
                    ixx="0.0001" ixy="0" ixz="0"
                    iyy="0.0001" iyz="0"
                    izz="0.0001"
                />
        </inertial>
    </link>
    <joint name="imu_joint" type="fixed">
            <axis rpy="0 0 0" xyz="0 0 0"/>
            <parent link="base_link"/>
            <child link="imu_link"/>
            <origin xyz="0 0 0.0"/>
    </joint>
	<!-- ..................gps sensor link.................. -->

	<link name="gps">
       <inertial>
        <origin xyz="0 0 0" rpy=" 0 0 0" />
        <mass value="0.01" />
        <inertia
	  ixx="0.00000015" ixy="0" ixz="0"
	  iyy="0.00000015" iyz="0"
	  izz="0.00000015"
	  />
	</inertial>
		
	<collision>
    	 <origin xyz="0 0 0" rpy=" 0 0 0" />
	 <geometry>
	   <box size="0.02 0.02 0.02"/>
	 </geometry>
	</collision>
	
	<visual>
          <origin xyz="0 0 0" rpy=" 0 0 0" />
	  <geometry>
	    <box size="0.02 0.02 0.02"/>
	  </geometry>
	</visual>

      </link>
      <joint type="fixed" name="GPS_sensor_joint">
	<axis xyz="1 0 0" rpy=" 0 0 0" />
	<origin xyz="0.08 0 0.07" />
	<child  link="gps"/>
	<parent	link="base_link"/>
      </joint>

 
    <gazebo reference="left_forward_wheel"> 
        <material>Gazebo/DarkGrey</material> 
    </gazebo> 
    <gazebo reference="left_back_wheel"> 
        <material>Gazebo/DarkGrey</material> 
    </gazebo> 
    <gazebo reference="right_forward_wheel"> 
        <material>Gazebo/DarkGrey</material> 
    </gazebo> 
    <gazebo reference="right_back_wheel"> 
        <material>Gazebo/DarkGrey</material> 
    </gazebo>
    <gazebo reference="base_link"> 
        <material>Gazebo/Gold</material> 
    </gazebo>
    <gazebo reference="imu_link"> 
        <material>Gazebo/GreenGlow</material> 
    </gazebo>
        
    <!--gazebo>
            <plugin name="gazebo_ros_control" filename="libgazebo_ros_control.so">
              <robotNamespace>/</robotNamespace>
              <legacyModeNS>false</legacyModeNS>
            </plugin>
    </gazebo-->

    
</robot>